<?xml version="1.0"?>
<robot xmlns:xacro="http://www.ros.org/wiki/xacro">

	<link name="base_link"/>

	<joint name="base_joint" type="fixed">
		<parent link="base_link"/>
		<child link="torso"/>
		<origin xyz="0 0 0.024" rpy="0 0 0"/>
	</joint>
	

	<!-- TORSO -->
	<link name="torso">
		<xacro:visuals_collisions_torso/>
		<inertial> <!-- Dummy values from Darwin OP -->
			<origin xyz="-0.003053 -0.038651 -0.019268" />
			<mass value="0.97559947"/>
			<inertia ixx="3.1081800"  ixy="-0.25460189"  ixz="2.0318174" iyy="6.3787776" iyz="0.16417863" izz="5.3316425" />
		</inertial>
	</link>

<!-- IMU properties -->
<joint name="imu_joint" type="floating">
    <parent link="base_link"/>
    <child link="torso"/>
    <origin xyz="0.0 0.0 0.033" rpy="0.0 0.0 0.0"/>
</joint>
<!--
<link name="imu_link">
    <inertial>
        <origin xyz="0.0 0.0 0.0" rpy="0.0 0.0 0.0" />
        <mass value="0.00001"/>
        <inertia
            ixx="1.0" ixy="0.0"  ixz="0.0"
            iyy="1.0" iyz="0.0"
            izz="1.0" />
    </inertial>
</link>
-->
  
	<gazebo>
        <plugin filename="libhector_gazebo_ros_imu.so" name="gazebo_ros_imu">
          <bodyName>torso</bodyName>
          <updateRate>50</updateRate>
          <serviceName>/hros5/imu_service</serviceName>
          <topicName>/hros5/imu</topicName>
          <gaussianNoise>0</gaussianNoise>
          <xyzOffset>0 0 0</xyzOffset>
          <rpyOffset>0 0 -0.703220730592</rpyOffset>
        </plugin>     
      </gazebo>

</robot>