<?xml version="1.0"?>
<robot xmlns:xacro="http://www.ros.org/wiki/xacro">

	<joint name="HeadYaw" type="revolute">
		<parent link="torso"/>
		<child link="LowerHead"/>
		<origin xyz="0.0035 0 0.1115" rpy="0 0 0"/>
		<axis xyz="0 0 1"/>
		<limit lower="-2.6179939" upper="2.6179939" effort="2.5" velocity="5.759586525"/>
	</joint>
	<link name="LowerHead">
		<xacro:visuals_collisions_lower_head/>
		<inertial> <!-- Dummy values from Darwin OP -->
			<origin xyz="0.001424 -0.016567 -0.007128" />
			<mass value="0.024357719"/>
			<inertia ixx="0.0051411124"  ixy="-0.00057530255"  ixz="-0.000024729049" iyy="0.0081915737" iyz="-0.000019223094" izz="0.0011379812" />
	    </inertial>
	</link>
	<joint name="HeadPitch" type="revolute">
		<parent link="LowerHead"/>
		<child link="UpperHeadBase"/>
		<origin xyz="-0.01 0 0.049" rpy="0 0 0"/>
		<axis xyz="0 -1 0"/>
		<limit upper="0.4" lower="-0.25" effort="2.5" velocity="5.759586525"/>
	</joint>
	<link name="UpperHeadBase">
		<xacro:visuals_collisions_upper_head_base/>
		<inertial> <!-- Dummy values from Darwin OP -->
			<origin xyz="0.000064 -0.018565 -0.007667" />
			<mass value="0.15804192"/>
			<inertia ixx="0.1239683"  ixy="0.000078494368"  ixz="0.000007645979" iyy="0.11783781" iyz="0.0012199205" izz="0.1583601" />
	    </inertial>
	</link>
	<joint name="HeadPitchDummy" type="continuous">
		<parent link="UpperHeadBase"/>
		<child link="UpperHeadMotor"/>
		<origin xyz="-0.00225 0 0.046" rpy="0 0 0"/>
		<axis xyz="0 1 0"/>
		<mimic joint="HeadPitch" multiplier="1.0"/>
	</joint>
	<link name="UpperHeadMotor">
		<xacro:visuals_collisions_upper_head_motor/>
		<inertial> <!-- dummy values for gazebo -->
			<mass value="0.2e-5" />
			<origin xyz="0 0 0"/>
			<inertia ixx="1e-9" ixy="0" ixz="0" iyy="1e-9" iyz="0" izz="1e-9" />
		</inertial>
	</link>
	<joint name="HeadPitchDummy2" type="continuous">
		<parent link="LowerHead"/>
		<child link="UpperHeadBack"/>
		<origin xyz="-0.0525 0 0.021" rpy="0 0 0"/>
		<axis xyz="0 1 0"/>
		<mimic joint="HeadPitch" multiplier="-0.65"/>
	</joint>
	<link name="UpperHeadBack">
		<xacro:visuals_collisions_upper_head_back/>
		<inertial> <!-- dummy values for gazebo -->
			<mass value="0.2e-5" />
			<origin xyz="0 0 0"/>
			<inertia ixx="1e-9" ixy="0" ixz="0" iyy="1e-9" iyz="0" izz="1e-9" />
		</inertial>
	</link>

<!-- Camera properties -->
<xacro:property name="pi" value="3.1415926535897931" />

<!-- openni2
<joint name="camera_rgb_joint" type="fixed">
	<parent link="UpperHeadBase" />
	<child link="camera_rgb_optical_frame" />
	<origin xyz="0.0 0.0 0.0" rpy="${pi/2} ${pi} ${pi/2}" />
</joint>
<link name="camera_rgb_optical_frame" />

<joint name="camera_depth_joint" type="fixed">
	<parent link="UpperHeadBase" />
	<child link="camera_depth_optical_frame" />
	<origin xyz="0.0 0.0 0.0" rpy="${pi/2} ${pi} ${pi/2}" />
</joint>
<link name="camera_depth_optical_frame" />

<joint name="camera_depth_frame" type="fixed">
	<parent link="UpperHeadBase" />
	<child link="camera_depth_frame_link" />
	<origin xyz="0.0 0.0 0.0" />
</joint>

<link name="camera_depth_frame_link" />

-->

<joint name="r200_frame" type="fixed">
	<parent link="UpperHeadBase" />
	<child link="realsense_frame" />
	<origin xyz="0.0 0.0 0.0" rpy="${pi/2} ${pi} ${pi/2}" />
</joint>
<link name="realsense_frame" />

<!--
<joint name="camera_color_joint" type="fixed">
	<parent link="UpperHeadBase" />
	<child link="camera_color_optical_frame" />
	<origin xyz="0.0 0.0 0.0" rpy="${pi/2} ${pi} ${pi/2}" />
</joint>
<link name="camera_color_optical_frame" />
-->
<!-- ROS REP LINKS -->
	<joint name="gaze_joint" type="fixed">
		<parent link="UpperHeadBase"/>
		<child link="gaze"/>
		<origin xyz="0 0 0" rpy="0 0 0"/>
	</joint>
	<link name="gaze"/>

</robot>
